<?xml version="1.0"?>
<robot xmlns:xacro="http://www.ros.org/wiki/xacro">

    <xacro:include filename="inertial_macros.xacro" />

    <!-- MATERIALS -->

    <material name="white">
        <color rgba="1 1 1 1" />
    </material>

    <material name="black">
        <color rgba="0 0 0 1" />
    </material>

    <material name="phone">
        <color rgba="0 0 0 0.75" />
    </material>

    <material name="blue">
        <color rgba="0.0156 0.23137 0.3607 1" />
    </material>

    <material name="orange">
        <color rgba="1 0.3 0.1 1" />
    </material>

    <link name="base_link">

    </link>

    <!-- FRAME LINK -->

    <joint name="frame_joint" type="fixed">
        <parent link="base_link"/>
        <child link="frame"/>
        <origin xyz="0 0 0"/>
    </joint>

    <link name="frame">
        <visual>
            <origin xyz="0 0 0"/>
            <geometry>
                <mesh filename="file://$(find hexapod)/meshes/frame.stl" scale="0.001 0.001 0.001"/>
            </geometry>
            <material name="white"/>
        </visual>
        <collision>
            <origin xyz="0 0 0"/>
            <geometry>
                <mesh filename="file://$(find hexapod)/meshes/frame.stl" scale="0.001 0.001 0.001"/>
            </geometry>
        </collision>
        <xacro:inertial_box mass="0.174" x="0" y="0" z="0">
            <origin xyz="0 0 0"/>
        </xacro:inertial_box>
    </link>
    <gazebo reference="frame">
        <material>Gazebo/White </material>
    </gazebo>

    <!-- FRAME SERVOS -->

    <joint name="servo1_joint" type="fixed">
        <parent link="frame"/>
        <child link="servo1"/>
        <origin xyz="0 0 0"/>
    </joint>

    <link name="servo1">
        <visual>
            <origin xyz="0.057 0.075 0.0075" rpy="${pi/2} 0.0 ${pi/4}"/>
            <geometry>
                <box size="0.0405 0.0395 0.02"/>
            </geometry>
            <material name="black"/>
        </visual>
        <collision>
            <origin xyz="0.057 0.075 0.0075" rpy="${pi/2} 0.0 ${pi/4}"/>
            <geometry>
                <box size="0.0405 0.0395 0.02"/>
            </geometry>
        </collision>
        <xacro:inertial_box mass="0.055" x="0.0405" y="0.0395" z="0.02">
            <origin xyz="0.057 0.075 0.0075" rpy="${pi/2} 0.0 ${pi/4}"/>
        </xacro:inertial_box>
    </link>
    <gazebo reference="servo1">
        <material>Gazebo/Black</material>
    </gazebo>

    <joint name="servo2_joint" type="fixed">
        <parent link="frame"/>
        <child link="servo2"/>
        <origin xyz="0 0 0"/>
    </joint>

    <link name="servo2">
        <visual>
            <origin xyz="0.07 0 0.0075" rpy="${pi/2} 0.0 0"/>
            <geometry>
                <box size="0.0405 0.0395 0.02"/>
            </geometry>
            <material name="black"/>
        </visual>
        <collision>
            <origin xyz="0.07 0 0.0075" rpy="${pi/2} 0.0 0"/>
            <geometry>
                <box size="0.0405 0.0395 0.02"/>
            </geometry>
        </collision>
        <xacro:inertial_box mass="0.055" x="0.0405" y="0.0395" z="0.02">
            <origin xyz="0.07 0 0.0075" rpy="${pi/2} 0.0 0"/>
        </xacro:inertial_box>
    </link>
    <gazebo reference="servo2">
        <material>Gazebo/Black</material>
    </gazebo>

    <joint name="servo3_joint" type="fixed">
        <parent link="frame"/>
        <child link="servo3"/>
        <origin xyz="0 0 0"/>
    </joint>

    <link name="servo3">
        <visual>
            <origin xyz="0.055 -0.078 0.0075" rpy="${pi/2} 0.0 -${pi/4}"/>
            <geometry>
                <box size="0.0405 0.0395 0.02"/>
            </geometry>
            <material name="black"/>
        </visual>
        <collision>
            <origin xyz="0.055 -0.078 0.0075" rpy="${pi/2} 0.0 -${pi/4}"/>
            <geometry>
                <box size="0.0405 0.0395 0.02"/>
            </geometry>
        </collision>
        <xacro:inertial_box mass="0.055" x="0.0405" y="0.0395" z="0.02">
            <origin xyz="0.055 -0.078 0.0075" rpy="${pi/2} 0.0 -${pi/4}"/>
        </xacro:inertial_box>
    </link>
    <gazebo reference="servo3">
        <material>Gazebo/Black</material>
    </gazebo>

    <joint name="servo4_joint" type="fixed">
        <parent link="frame"/>
        <child link="servo4"/>
        <origin xyz="0 0 0"/>
    </joint>

    <link name="servo4">
        <visual>
            <origin xyz="-0.055 -0.078 0.0075" rpy="${pi/2} 0.0 ${pi/4}"/>
            <geometry>
                <box size="0.0405 0.0395 0.02"/>
            </geometry>
            <material name="black"/>
        </visual>
        <collision>
            <origin xyz="-0.055 -0.078 0.0075" rpy="${pi/2} 0.0 ${pi/4}"/>
            <geometry>
                <box size="0.0405 0.0395 0.02"/>
            </geometry>
        </collision>
        <xacro:inertial_box mass="0.055" x="0.0405" y="0.0395" z="0.02">
            <origin xyz="-0.055 -0.078 0.0075" rpy="${pi/2} 0.0 ${pi/4}"/>
        </xacro:inertial_box>
    </link>
    <gazebo reference="servo4">
        <material>Gazebo/Black</material>
    </gazebo>

    <joint name="servo5_joint" type="fixed">
        <parent link="frame"/>
        <child link="servo5"/>
        <origin xyz="0 0 0"/>
    </joint>

    <link name="servo5">
        <visual>
            <origin xyz="-0.07 0 0.0075" rpy="${pi/2} 0.0 0"/>
            <geometry>
                <box size="0.0405 0.0395 0.02"/>
            </geometry>
            <material name="black"/>
        </visual>
        <collision>
            <origin xyz="-0.07 0 0.0075" rpy="${pi/2} 0.0 0"/>
            <geometry>
                <box size="0.0405 0.0395 0.02"/>
            </geometry>
        </collision>
        <xacro:inertial_box mass="0.055" x="0.0405" y="0.0395" z="0.02">
            <origin xyz="-0.07 0 0.0075" rpy="${pi/2} 0.0 0"/>
        </xacro:inertial_box>
    </link>
    <gazebo reference="servo5">
        <material>Gazebo/Black</material>
    </gazebo>

    <joint name="servo6_joint" type="fixed">
        <parent link="frame"/>
        <child link="servo6"/>
        <origin xyz="0 0 0"/>
    </joint>

    <link name="servo6">
        <visual>
            <origin xyz="-0.057 0.075 0.0075" rpy="${pi/2} 0.0 -${pi/4}"/>
            <geometry>
                <box size="0.0405 0.0395 0.02"/>
            </geometry>
            <material name="black"/>
        </visual>
        <collision>
            <origin xyz="-0.057 0.075 0.0075" rpy="${pi/2} 0.0 -${pi/4}"/>
            <geometry>
                <box size="0.0405 0.0395 0.02"/>
            </geometry>
        </collision>
        <xacro:inertial_box mass="0.055" x="0.0405" y="0.0395" z="0.02">
            <origin xyz="-0.057 0.075 0.0075"/>
        </xacro:inertial_box>
    </link>
    <gazebo reference="servo6">
        <material>Gazebo/Black</material>
    </gazebo>

    <!-- LEG SERVOS -->

    <!-- LEG 1 (RF) -->

    <joint name="coxa1_joint" type="revolute">
        <parent link="servo1"/>
        <child link="coxa1"/>
        <origin xyz="0.06 0.085 -0.0025" rpy="0 0 ${pi/4}"/>
        <axis xyz="0 0 1" />
        <limit lower="-0.785398" upper="0.785398" effort="0.8825985000000001" velocity="1.0"/>
    </joint>

    <link name="coxa1">
        <visual>
            <origin xyz="0 0 -0.0025"/>
            <geometry>
                <mesh filename="file://$(find hexapod)/meshes/right_coxa.stl" scale="0.001 0.001 0.001"/>
            </geometry>
            <material name="white"/>
        </visual>
        <collision>
            <origin xyz="0 0 -0.0025"/>
            <geometry>
                <mesh filename="file://$(find hexapod)/meshes/right_coxa.stl" scale="0.001 0.001 0.001"/>
            </geometry>
        </collision>
        <xacro:inertial_box mass="0.015" x="0.01" y="0.01" z="0.01">
            <origin xyz="0.025 0 0.0025" rpy="0 0 0"/>
        </xacro:inertial_box>
    </link>
    <gazebo reference="coxa1">
        <material>Gazebo/White</material>
    </gazebo>

    <joint name="servo7_joint" type="fixed">
        <parent link="coxa1"/>
        <child link="servo7"/>
        <origin xyz="0 0 0"/>
    </joint>

    <link name="servo7">
        <visual>
            <origin xyz="0.045 0 0.0095" rpy="0 ${pi/2} 0"/>
            <geometry>
                <box size="0.0405 0.0395 0.02"/>
            </geometry>
            <material name="black"/>
        </visual>
        <collision>
            <origin xyz="0.045 0 0.0095" rpy="0 ${pi/2} 0"/>
            <geometry>
                <box size="0.0405 0.0395 0.02"/>
            </geometry>
        </collision>
        <xacro:inertial_box mass="0.055" x="0.0405" y="0.0395" z="0.02">
            <origin xyz="0.045 0 0.0095" rpy="0 ${pi/2} 0"/>
        </xacro:inertial_box>
    </link>
    <gazebo reference="servo7">
        <material>Gazebo/Black</material>
    </gazebo>

    <joint name="femur1_joint" type="revolute">
        <parent link="servo7"/>
        <child link="femur1"/>
        <origin xyz="0.045 0 0.02" rpy="${pi/2} ${pi/4} ${pi}"/>
        <axis xyz="0 0 1" />
        <limit lower="-0.785398" upper="0.785398" effort="0.8825985000000001" velocity="1.0"/>
    </joint>

    <link name="femur1">
        <visual>
            <origin xyz="-0.08 0 -0.0125"/>
            <geometry>
                <mesh filename="file://$(find hexapod)/meshes/right_femur.stl" scale="0.001 0.001 0.001"/>
            </geometry>
            <material name="white"/>
        </visual>
        <collision>
             <origin xyz="-0.08 0 -0.0125"/>
            <geometry>
                <mesh filename="file://$(find hexapod)/meshes/right_femur.stl" scale="0.001 0.001 0.001"/>
            </geometry>
        </collision>
        <xacro:inertial_box mass="0.015" x="0.01" y="0.01" z="0.01">
             <origin xyz="-0.08 0 -0.0125"/>
        </xacro:inertial_box>
    </link>
    <gazebo reference="femur1">
        <material>Gazebo/White</material>
    </gazebo>

    <joint name="servo13_joint" type="revolute">
        <parent link="femur1"/>
        <child link="servo13"/>
        <origin xyz="-0.0775 0 0" rpy="0 0 ${pi/4}"/>
        <axis xyz="0 0 1" />
        <limit lower="-0.785398" upper="0.785398" effort="0.8825985000000001" velocity="1.0"/>
    </joint>

    <link name="servo13">
        <visual>
            <origin xyz="-0.008 0 0" rpy="${pi/2} ${pi/2} 0"/>
            <geometry>
                <box size="0.0405 0.0395 0.02"/>
            </geometry>
            <material name="black"/>
        </visual>
        <collision>
            <origin xyz="-0.008 0 0" rpy="${pi/2} ${pi/2} 0"/>
            <geometry>
                <box size="0.0405 0.0395 0.02"/>
            </geometry>
        </collision>
        <xacro:inertial_box mass="0.055" x="0.0405" y="0.0395" z="0.02">
            <origin xyz="-0.008 0 0" rpy="${pi/2} ${pi/2} 0"/>
        </xacro:inertial_box>
    </link>
    <gazebo reference="servo13">
        <material>Gazebo/Black</material>
    </gazebo>

    <joint name="tibia1_joint" type="fixed">
        <parent link="servo13"/>
        <child link="tibia1"/>
        <origin xyz="0 0 0" rpy="-${pi/2} 0 -0.85"/>
    </joint>

    <link name="tibia1">
        <visual>
            <origin xyz="-0.055 0 0.005"/>
            <geometry>
                <mesh filename="file://$(find hexapod)/meshes/right_tibia.stl" scale="0.001 0.001 0.001"/>
            </geometry>
            <material name="white"/>
        </visual>
        <collision>
            <origin xyz="-0.055 0 0.005"/>
            <geometry>
                <mesh filename="file://$(find hexapod)/meshes/right_tibia.stl" scale="0.001 0.001 0.001"/>
            </geometry>
        </collision>
        <xacro:inertial_box mass="0.015" x="0.01" y="0.01" z="0.01">
             <origin xyz="-0.055 0 0.005"/>
        </xacro:inertial_box>
    </link>
    <gazebo reference="tibia1">
        <material>Gazebo/White</material>
    </gazebo>

    <joint name="shield1_joint" type="fixed">
        <parent link="tibia1"/>
        <child link="shield1"/>
        <origin xyz="0 0 0" rpy="0 0 0"/>
    </joint>

    <link name="shield1">
        <visual>
            <origin xyz="-0.055 0 0"/>
            <geometry>
                <mesh filename="file://$(find hexapod)/meshes/shield.stl" scale="0.001 0.001 0.001"/>
            </geometry>
            <material name="blue"/>
        </visual>
        <collision>
            <origin xyz="-0.055 0 0"/>
            <geometry>
                <mesh filename="file://$(find hexapod)/meshes/shield.stl" scale="0.001 0.001 0.001"/>
            </geometry>
        </collision>
        <xacro:inertial_box mass="0.015" x="0.01" y="0.01" z="0.01">
             <origin xyz="-0.055 0 0"/>
        </xacro:inertial_box>
    </link>
    <gazebo reference="shield1">
        <material>Gazebo/Blue</material>
    </gazebo>

    <joint name="sensor1_joint" type="fixed">
        <parent link="tibia1"/>
        <child link="sensor1"/>
        <origin xyz="0 0 0" rpy="0 0 0"/>
    </joint>

    <link name="sensor1">
        <visual>
            <origin xyz="-0.0425 0.005 -0.125"/>
            <geometry>
                <mesh filename="file://$(find hexapod)/meshes/micro_switch_tip.stl" scale="0.001 0.001 0.001"/>
            </geometry>
            <material name="white"/>
        </visual>
        <collision>
            <origin xyz="-0.0425 0.005 -0.125"/>
            <geometry>
                <mesh filename="file://$(find hexapod)/meshes/micro_switch_tip.stl" scale="0.001 0.001 0.001"/>
            </geometry>
        </collision>
        <xacro:inertial_box mass="0.015" x="0.01" y="0.01" z="0.01">
             <origin xyz="-0.0425 0.005 -0.125"/>
        </xacro:inertial_box>
    </link>
    <gazebo reference="sensor1">
        <material>Gazebo/White</material>
    </gazebo>

    <!-- LEG 2 (RM) -->

    <joint name="coxa2_joint" type="revolute">
        <parent link="servo2"/>
        <child link="coxa2"/>
        <origin xyz="0.08 0 -0.0025"/>
        <axis xyz="0 0 1" />
        <limit lower="-0.785398" upper="0.785398" effort="0.8825985000000001" velocity="1.0"/>
    </joint>

    <link name="coxa2">
        <visual>
            <origin xyz="0 0 -0.0025"/>
            <geometry>
                <mesh filename="file://$(find hexapod)/meshes/right_coxa.stl" scale="0.001 0.001 0.001"/>
            </geometry>
            <material name="white"/>
        </visual>
        <collision>
            <origin xyz="0 0 -0.0025"/>
            <geometry>
                <mesh filename="file://$(find hexapod)/meshes/right_coxa.stl" scale="0.001 0.001 0.001"/>
            </geometry>
        </collision>
        <xacro:inertial_box mass="0.015" x="0.01" y="0.01" z="0.01">
            <origin xyz="0.025 0 0.0025" rpy="0 0 0"/>
        </xacro:inertial_box>
    </link>
    <gazebo reference="coxa2">
        <material>Gazebo/White</material>
    </gazebo>

    <joint name="servo8_joint" type="fixed">
        <parent link="coxa2"/>
        <child link="servo8"/>
        <origin xyz="0 0 0"/>
    </joint>

    <link name="servo8">
        <visual>
            <origin xyz="0.045 0 0.0095" rpy="0 ${pi/2} 0"/>
            <geometry>
                <box size="0.0405 0.0395 0.02"/>
            </geometry>
            <material name="black"/>
        </visual>
        <collision>
            <origin xyz="0.045 0 0.0095" rpy="0 ${pi/2} 0"/>
            <geometry>
                <box size="0.0405 0.0395 0.02"/>
            </geometry>
        </collision>
        <xacro:inertial_box mass="0.055" x="0.0405" y="0.0395" z="0.02">
            <origin xyz="0.045 0 0.0095" rpy="0 ${pi/2} 0"/>
        </xacro:inertial_box>
    </link>
    <gazebo reference="servo8">
        <material>Gazebo/Black</material>
    </gazebo>

    <joint name="femur2_joint" type="revolute">
        <parent link="servo8"/>
        <child link="femur2"/>
        <origin xyz="0.045 0 0.02" rpy="${pi/2} ${pi/4} ${pi}"/>
        <axis xyz="0 0 1" />
        <limit lower="-0.785398" upper="0.785398" effort="0.8825985000000001" velocity="1.0"/>
    </joint>

    <link name="femur2">
        <visual>
            <origin xyz="-0.08 0 -0.0125"/>
            <geometry>
                <mesh filename="file://$(find hexapod)/meshes/right_femur.stl" scale="0.001 0.001 0.001"/>
            </geometry>
            <material name="white"/>
        </visual>
        <collision>
             <origin xyz="-0.08 0 -0.0125"/>
            <geometry>
                <mesh filename="file://$(find hexapod)/meshes/right_femur.stl" scale="0.001 0.001 0.001"/>
            </geometry>
        </collision>
        <xacro:inertial_box mass="0.015" x="0.01" y="0.01" z="0.01">
             <origin xyz="-0.08 0 -0.0125"/>
        </xacro:inertial_box>
    </link>
    <gazebo reference="femur2">
        <material>Gazebo/White</material>
    </gazebo>

    <joint name="servo14_joint" type="revolute">
        <parent link="femur2"/>
        <child link="servo14"/>
        <origin xyz="-0.0775 0 0" rpy="0 0 ${pi/4}"/>
        <axis xyz="0 0 1" />
        <limit lower="-0.785398" upper="0.785398" effort="0.8825985000000001" velocity="1.0"/>
    </joint>

    <link name="servo14">
        <visual>
            <origin xyz="-0.008 0 0" rpy="${pi/2} ${pi/2} 0"/>
            <geometry>
                <box size="0.0405 0.0395 0.02"/>
            </geometry>
            <material name="black"/>
        </visual>
        <collision>
            <origin xyz="-0.008 0 0" rpy="${pi/2} ${pi/2} 0"/>
            <geometry>
                <box size="0.0405 0.0395 0.02"/>
            </geometry>
        </collision>
        <xacro:inertial_box mass="0.055" x="0.0405" y="0.0395" z="0.02">
            <origin xyz="-0.008 0 0" rpy="${pi/2} ${pi/2} 0"/>
        </xacro:inertial_box>
    </link>
    <gazebo reference="servo14">
        <material>Gazebo/Black</material>
    </gazebo>

    <joint name="tibia2_joint" type="fixed">
        <parent link="servo14"/>
        <child link="tibia2"/>
        <origin xyz="0 0 0" rpy="-${pi/2} 0 -0.85"/>
    </joint>

    <link name="tibia2">
        <visual>
            <origin xyz="-0.055 0 0.005"/>
            <geometry>
                <mesh filename="file://$(find hexapod)/meshes/right_tibia.stl" scale="0.001 0.001 0.001"/>
            </geometry>
            <material name="white"/>
        </visual>
        <collision>
            <origin xyz="-0.055 0 0.005"/>
            <geometry>
                <mesh filename="file://$(find hexapod)/meshes/right_tibia.stl" scale="0.001 0.001 0.001"/>
            </geometry>
        </collision>
        <xacro:inertial_box mass="0.015" x="0.01" y="0.01" z="0.01">
             <origin xyz="-0.055 0 0.005"/>
        </xacro:inertial_box>
    </link>
    <gazebo reference="tibia2">
        <material>Gazebo/White</material>
    </gazebo>

    <joint name="shield2_joint" type="fixed">
        <parent link="tibia2"/>
        <child link="shield2"/>
        <origin xyz="0 0 0" rpy="0 0 0"/>
    </joint>

    <link name="shield2">
        <visual>
            <origin xyz="-0.055 0 0"/>
            <geometry>
                <mesh filename="file://$(find hexapod)/meshes/shield.stl" scale="0.001 0.001 0.001"/>
            </geometry>
            <material name="blue"/>
        </visual>
        <collision>
            <origin xyz="-0.055 0 0"/>
            <geometry>
                <mesh filename="file://$(find hexapod)/meshes/shield.stl" scale="0.001 0.001 0.001"/>
            </geometry>
        </collision>
        <xacro:inertial_box mass="0.015" x="0.01" y="0.01" z="0.01">
            <origin xyz="-0.055 0 0"/>
        </xacro:inertial_box>
    </link>
    <gazebo reference="shield2">
        <material>Gazebo/Blue</material>
    </gazebo>

    <joint name="sensor2_joint" type="fixed">
        <parent link="tibia2"/>
        <child link="sensor2"/>
        <origin xyz="0 0 0" rpy="0 0 0"/>
    </joint>

    <link name="sensor2">
        <visual>
            <origin xyz="-0.0425 0.005 -0.125"/>
            <geometry>
                <mesh filename="file://$(find hexapod)/meshes/micro_switch_tip.stl" scale="0.001 0.001 0.001"/>
            </geometry>
            <material name="white"/>
        </visual>
        <collision>
            <origin xyz="-0.0425 0.005 -0.125"/>
            <geometry>
                <mesh filename="file://$(find hexapod)/meshes/micro_switch_tip.stl" scale="0.001 0.001 0.001"/>
            </geometry>
        </collision>
        <xacro:inertial_box mass="0.015" x="0.01" y="0.01" z="0.01">
             <origin xyz="-0.0425 0.005 -0.125"/>
        </xacro:inertial_box>
    </link>
    <gazebo reference="sensor2">
        <material>Gazebo/White</material>
    </gazebo>

    <!-- LEG 3 (RB) -->

    <joint name="coxa3_joint" type="revolute">
        <parent link="servo3"/>
        <child link="coxa3"/>
        <origin xyz="0.06 -0.085 -0.0025" rpy="0 0 -${pi/4}"/>
        <axis xyz="0 0 1" />
        <limit lower="-0.785398" upper="0.785398" effort="0.8825985000000001" velocity="1.0"/>
    </joint>

    <link name="coxa3">
        <visual>
            <origin xyz="0 0 -0.0025"/>
            <geometry>
                <mesh filename="file://$(find hexapod)/meshes/right_coxa.stl" scale="0.001 0.001 0.001"/>
            </geometry>
            <material name="white"/>
        </visual>
        <collision>
            <origin xyz="0 0 -0.0025"/>
            <geometry>
                <mesh filename="file://$(find hexapod)/meshes/right_coxa.stl" scale="0.001 0.001 0.001"/>
            </geometry>
        </collision>
        <xacro:inertial_box mass="0.015" x="0.01" y="0.01" z="0.01">
            <origin xyz="0 0 0.0025" rpy="0 0 0"/>
        </xacro:inertial_box>
    </link>
    <gazebo reference="coxa3">
        <material>Gazebo/White</material>
    </gazebo>

    <joint name="servo9_joint" type="fixed">
        <parent link="coxa3"/>
        <child link="servo9"/>
        <origin xyz="0 0 0"/>
    </joint>

    <link name="servo9">
        <visual>
            <origin xyz="0.045 0 0.0095" rpy="0 ${pi/2} 0"/>
            <geometry>
                <box size="0.0405 0.0395 0.02"/>
            </geometry>
            <material name="black"/>
        </visual>
        <collision>
            <origin xyz="0.045 0 0.0095" rpy="0 ${pi/2} 0"/>
            <geometry>
                <box size="0.0405 0.0395 0.02"/>
            </geometry>
        </collision>
        <xacro:inertial_box mass="0.055" x="0.0405" y="0.0395" z="0.02">
            <origin xyz="0.045 0 0.0095" rpy="0 ${pi/2} 0"/>
        </xacro:inertial_box>
    </link>
    <gazebo reference="servo9">
        <material>Gazebo/Black</material>
    </gazebo>

    <joint name="femur3_joint" type="revolute">
        <parent link="servo9"/>
        <child link="femur3"/>
        <origin xyz="0.045 0 0.02" rpy="${pi/2} ${pi/4} ${pi}"/>
        <axis xyz="0 0 1" />
        <limit lower="-0.785398" upper="0.785398" effort="0.8825985000000001" velocity="1.0"/>
    </joint>

    <link name="femur3">
        <visual>
            <origin xyz="-0.08 0 -0.0125"/>
            <geometry>
                <mesh filename="file://$(find hexapod)/meshes/right_femur.stl" scale="0.001 0.001 0.001"/>
            </geometry>
            <material name="white"/>
        </visual>
        <collision>
             <origin xyz="-0.08 0 -0.0125"/>
            <geometry>
                <mesh filename="file://$(find hexapod)/meshes/right_femur.stl" scale="0.001 0.001 0.001"/>
            </geometry>
        </collision>
        <xacro:inertial_box mass="0.015" x="0.01" y="0.01" z="0.01">
             <origin xyz="-0.08 0 -0.0125"/>
        </xacro:inertial_box>
    </link>
    <gazebo reference="femur3">
        <material>Gazebo/White</material>
    </gazebo>

    <joint name="servo15_joint" type="revolute">
        <parent link="femur3"/>
        <child link="servo15"/>
        <origin xyz="-0.0775 0 0" rpy="0 0 ${pi/4}"/>
        <axis xyz="0 0 1" />
        <limit lower="-0.785398" upper="0.785398" effort="0.8825985000000001" velocity="1.0"/>
    </joint>

    <link name="servo15">
        <visual>
            <origin xyz="-0.008 0 0" rpy="${pi/2} ${pi/2} 0"/>
            <geometry>
                <box size="0.0405 0.0395 0.02"/>
            </geometry>
            <material name="black"/>
        </visual>
        <collision>
            <origin xyz="-0.008 0 0" rpy="${pi/2} ${pi/2} 0"/>
            <geometry>
                <box size="0.0405 0.0395 0.02"/>
            </geometry>
        </collision>
        <xacro:inertial_box mass="0.055" x="0.0405" y="0.0395" z="0.02">
            <origin xyz="-0.008 0 0" rpy="${pi/2} ${pi/2} 0"/>
        </xacro:inertial_box>
    </link>
    <gazebo reference="servo15">
        <material>Gazebo/Black</material>
    </gazebo>

    <joint name="tibia3_joint" type="fixed">
        <parent link="servo15"/>
        <child link="tibia3"/>
        <origin xyz="0 0 0" rpy="-${pi/2} 0 -0.85"/>
    </joint>

    <link name="tibia3">
        <visual>
            <origin xyz="-0.055 0 0.005"/>
            <geometry>
                <mesh filename="file://$(find hexapod)/meshes/right_tibia.stl" scale="0.001 0.001 0.001"/>
            </geometry>
            <material name="white"/>
        </visual>
        <collision>
            <origin xyz="-0.055 0 0.005"/>
            <geometry>
                <mesh filename="file://$(find hexapod)/meshes/right_tibia.stl" scale="0.001 0.001 0.001"/>
            </geometry>
        </collision>
        <xacro:inertial_box mass="0.015" x="0.01" y="0.01" z="0.01">
            <origin xyz="-0.055 0 0.005"/>
        </xacro:inertial_box>
    </link>
    <gazebo reference="tibia3">
        <material>Gazebo/White</material>
    </gazebo>

    <joint name="shield3_joint" type="fixed">
        <parent link="tibia3"/>
        <child link="shield3"/>
        <origin xyz="0 0 0" rpy="0 0 0"/>
    </joint>

    <link name="shield3">
        <visual>
            <origin xyz="-0.055 0 0"/>
            <geometry>
                <mesh filename="file://$(find hexapod)/meshes/shield.stl" scale="0.001 0.001 0.001"/>
            </geometry>
            <material name="blue"/>
        </visual>
        <collision>
            <origin xyz="-0.055 0 0"/>
            <geometry>
                <mesh filename="file://$(find hexapod)/meshes/shield.stl" scale="0.001 0.001 0.001"/>
            </geometry>
        </collision>
        <xacro:inertial_box mass="0.015" x="0.01" y="0.01" z="0.01">
            <origin xyz="-0.055 0 0"/>
        </xacro:inertial_box>
    </link>
    <gazebo reference="shield3">
        <material>Gazebo/Blue</material>
    </gazebo>

    <joint name="sensor3_joint" type="fixed">
        <parent link="tibia3"/>
        <child link="sensor3"/>
        <origin xyz="0 0 0" rpy="0 0 0"/>
    </joint>

    <link name="sensor3">
        <visual>
            <origin xyz="-0.0425 0.005 -0.125"/>
            <geometry>
                <mesh filename="file://$(find hexapod)/meshes/micro_switch_tip.stl" scale="0.001 0.001 0.001"/>
            </geometry>
            <material name="white"/>
        </visual>
        <collision>
            <origin xyz="-0.0425 0.005 -0.125"/>
            <geometry>
                <mesh filename="file://$(find hexapod)/meshes/micro_switch_tip.stl" scale="0.001 0.001 0.001"/>
            </geometry>
        </collision>
        <xacro:inertial_box mass="0.015" x="0.01" y="0.01" z="0.01">
             <origin xyz="-0.0425 0.005 -0.125"/>
        </xacro:inertial_box>
    </link>
    <gazebo reference="sensor3">
        <material>Gazebo/White</material>
    </gazebo>

    <!-- LEG 4 (LB) -->

    <joint name="coxa4_joint" type="revolute">
        <parent link="servo4"/>
        <child link="coxa4"/>
        <origin xyz="-0.06 -0.085 -0.0025" rpy="0 0 -${(3*pi)/4}"/>
        <axis xyz="0 0 1" />
        <limit lower="-0.785398" upper="0.785398" effort="0.8825985000000001" velocity="1.0"/>
    </joint>

    <link name="coxa4">
        <visual>
            <origin xyz="0 0 -0.0025"/>
            <geometry>
                <mesh filename="file://$(find hexapod)/meshes/left_coxa.stl" scale="0.001 0.001 0.001"/>
            </geometry>
            <material name="white"/>
        </visual>
        <collision>
            <origin xyz="0 0 -0.0025"/>
            <geometry>
                <mesh filename="file://$(find hexapod)/meshes/left_coxa.stl" scale="0.001 0.001 0.001"/>
            </geometry>
        </collision>
        <xacro:inertial_box mass="0.015" x="0.01" y="0.01" z="0.01">
            <origin xyz="0 0 0.0025" rpy="0 0 0"/>
        </xacro:inertial_box>
    </link>
    <gazebo reference="coxa4">
        <material>Gazebo/White</material>
    </gazebo>

    <joint name="servo10_joint" type="fixed">
        <parent link="coxa4"/>
        <child link="servo10"/>
        <origin xyz="0 0 0"/>
    </joint>

    <link name="servo10">
        <visual>
            <origin xyz="0.045 0 0.0095" rpy="0 ${pi/2} 0"/>
            <geometry>
                <box size="0.0405 0.0395 0.02"/>
            </geometry>
            <material name="black"/>
        </visual>
        <collision>
            <origin xyz="0.045 0 0.0095" rpy="0 ${pi/2} 0"/>
            <geometry>
                <box size="0.0405 0.0395 0.02"/>
            </geometry>
        </collision>
        <xacro:inertial_box mass="0.055" x="0.0405" y="0.0395" z="0.02">
            <origin xyz="0.045 0 0.0095" rpy="0 ${pi/2} 0"/>
        </xacro:inertial_box>
    </link>
    <gazebo reference="servo10">
        <material>Gazebo/Black</material>
    </gazebo>

    <joint name="femur4_joint" type="revolute">
        <parent link="servo10"/>
        <child link="femur4"/>
        <origin xyz="0.045 0 0.02" rpy="${pi/2} ${pi/4} ${pi}"/>
        <axis xyz="0 0 1" />
        <limit lower="-0.785398" upper="0.785398" effort="0.8825985000000001" velocity="1.0"/>
    </joint>

    <link name="femur4">
        <visual>
            <origin xyz="-0.08 0 0.0125"/>
            <geometry>
                <mesh filename="file://$(find hexapod)/meshes/left_femur.stl" scale="0.001 0.001 0.001"/>
            </geometry>
            <material name="white"/>
        </visual>
        <collision>
             <origin xyz="-0.08 0 -0.0125"/>
            <geometry>
                <mesh filename="file://$(find hexapod)/meshes/left_femur.stl" scale="0.001 0.001 0.001"/>
            </geometry>
        </collision>
        <xacro:inertial_box mass="0.015" x="0.01" y="0.01" z="0.01">
             <origin xyz="-0.08 0 -0.0125"/>
        </xacro:inertial_box>
    </link>
    <gazebo reference="femur4">
        <material>Gazebo/White</material>
    </gazebo>

    <joint name="servo16_joint" type="revolute">
        <parent link="femur4"/>
        <child link="servo16"/>
        <origin xyz="-0.0775 0 0" rpy="0 0 ${pi/4}"/>
        <axis xyz="0 0 1" />
        <limit lower="-0.785398" upper="0.785398" effort="0.8825985000000001" velocity="1.0"/>
    </joint>

    <link name="servo16">
        <visual>
            <origin xyz="-0.008 0 0" rpy="${pi/2} ${pi/2} 0"/>
            <geometry>
                <box size="0.0405 0.0395 0.02"/>
            </geometry>
            <material name="black"/>
        </visual>
        <collision>
            <origin xyz="-0.008 0 0" rpy="${pi/2} ${pi/2} 0"/>
            <geometry>
                <box size="0.0405 0.0395 0.02"/>
            </geometry>
        </collision>
        <xacro:inertial_box mass="0.055" x="0.0405" y="0.0395" z="0.02">
            <origin xyz="-0.008 0 0" rpy="${pi/2} ${pi/2} 0"/>
        </xacro:inertial_box>
    </link>
    <gazebo reference="servo16">
        <material>Gazebo/Black</material>
    </gazebo>

    <joint name="tibia4_joint" type="fixed">
        <parent link="servo16"/>
        <child link="tibia4"/>
        <origin xyz="0 0 0" rpy="-${pi/2} 0 -0.85"/>
    </joint>

    <link name="tibia4">
        <visual>
            <origin xyz="-0.055 0 0.005"/>
            <geometry>
                <mesh filename="file://$(find hexapod)/meshes/left_tibia.stl" scale="0.001 0.001 0.001"/>
            </geometry>
            <material name="white"/>
        </visual>
        <collision>
            <origin xyz="-0.055 0 0.005"/>
            <geometry>
                <mesh filename="file://$(find hexapod)/meshes/left_tibia.stl" scale="0.001 0.001 0.001"/>
            </geometry>
        </collision>
        <xacro:inertial_box mass="0.015" x="0.01" y="0.01" z="0.01">
            <origin xyz="-0.055 0 0.005"/>
        </xacro:inertial_box>
    </link>
    <gazebo reference="tibia4">
        <material>Gazebo/White</material>
    </gazebo>

    <joint name="shield4_joint" type="fixed">
        <parent link="tibia4"/>
        <child link="shield4"/>
        <origin xyz="0 0 0" rpy="0 0 0"/>
    </joint>

    <link name="shield4">
        <visual>
            <origin xyz="-0.055 -0.01 0"/>
            <geometry>
                <mesh filename="file://$(find hexapod)/meshes/shield.stl" scale="0.001 0.001 0.001"/>
            </geometry>
            <material name="blue"/>
        </visual>
        <collision>
            <origin xyz="-0.055 -0.01 0"/>
            <geometry>
                <mesh filename="file://$(find hexapod)/meshes/shield.stl" scale="0.001 0.001 0.001"/>
            </geometry>
        </collision>
        <xacro:inertial_box mass="0.015" x="0.01" y="0.01" z="0.01">
            <origin xyz="-0.055 -0.01 0"/>
        </xacro:inertial_box>
    </link>
    <gazebo reference="shield4">
        <material>Gazebo/Blue</material>
    </gazebo>

    <joint name="sensor4_joint" type="fixed">
        <parent link="tibia4"/>
        <child link="sensor4"/>
        <origin xyz="0 0 0" rpy="0 0 0"/>
    </joint>

    <link name="sensor4">
        <visual>
            <origin xyz="-0.0425 -0.005 -0.125"/>
            <geometry>
                <mesh filename="file://$(find hexapod)/meshes/micro_switch_tip.stl" scale="0.001 0.001 0.001"/>
            </geometry>
            <material name="white"/>
        </visual>
        <collision>
            <origin xyz="-0.0425 -0.005 -0.125"/>
            <geometry>
                <mesh filename="file://$(find hexapod)/meshes/micro_switch_tip.stl" scale="0.001 0.001 0.001"/>
            </geometry>
        </collision>
        <xacro:inertial_box mass="0.015" x="0.01" y="0.01" z="0.01">
             <origin xyz="-0.0425 -0.005 -0.125"/>
        </xacro:inertial_box>
    </link>
    <gazebo reference="sensor4">
        <material>Gazebo/White</material>
    </gazebo>

    <!-- LEG 5 (LM) -->

    <joint name="coxa5_joint" type="revolute">
        <parent link="servo5"/>
        <child link="coxa5"/>
        <origin xyz="-0.08 0 -0.0025" rpy="0 0 ${pi}"/>
        <axis xyz="0 0 1" />
        <limit lower="-0.785398" upper="0.785398" effort="0.8825985000000001" velocity="1.0"/>
    </joint>

    <link name="coxa5">
        <visual>
            <origin xyz="0 0 -0.0025"/>
            <geometry>
                <mesh filename="file://$(find hexapod)/meshes/left_coxa.stl" scale="0.001 0.001 0.001"/>
            </geometry>
            <material name="white"/>
        </visual>
        <collision>
            <origin xyz="0 0 -0.0025"/>
            <geometry>
                <mesh filename="file://$(find hexapod)/meshes/left_coxa.stl" scale="0.001 0.001 0.001"/>
            </geometry>
        </collision>
        <xacro:inertial_box mass="0.015" x="0.01" y="0.01" z="0.01">
            <origin xyz="0 0 0.0025" rpy="0 0 0"/>
        </xacro:inertial_box>
    </link>
    <gazebo reference="coxa5">
        <material>Gazebo/White</material>
    </gazebo>

    <joint name="servo11_joint" type="fixed">
        <parent link="coxa5"/>
        <child link="servo11"/>
        <origin xyz="0 0 0"/>
    </joint>

    <link name="servo11">
        <visual>
            <origin xyz="0.045 0 0.0095" rpy="0 ${pi/2} 0"/>
            <geometry>
                <box size="0.0405 0.0395 0.02"/>
            </geometry>
            <material name="black"/>
        </visual>
        <collision>
            <origin xyz="0.045 0 0.0095" rpy="0 ${pi/2} 0"/>
            <geometry>
                <box size="0.0405 0.0395 0.02"/>
            </geometry>
        </collision>
        <xacro:inertial_box mass="0.055" x="0.0405" y="0.0395" z="0.02">
            <origin xyz="0.045 0 0.0095" rpy="0 ${pi/2} 0"/>
        </xacro:inertial_box>
    </link>
    <gazebo reference="servo11">
        <material>Gazebo/Black</material>
    </gazebo>

    <joint name="femur5_joint" type="revolute">
        <parent link="servo11"/>
        <child link="femur5"/>
        <origin xyz="0.045 0 0.02" rpy="${pi/2} ${pi/4} ${pi}"/>
        <axis xyz="0 0 1" />
        <limit lower="-0.785398" upper="0.785398" effort="0.8825985000000001" velocity="1.0"/>
    </joint>

    <link name="femur5">
        <visual>
            <origin xyz="-0.08 0 0.0125"/>
            <geometry>
                <mesh filename="file://$(find hexapod)/meshes/left_femur.stl" scale="0.001 0.001 0.001"/>
            </geometry>
            <material name="white"/>
        </visual>
        <collision>
             <origin xyz="-0.08 0 -0.0125"/>
            <geometry>
                <mesh filename="file://$(find hexapod)/meshes/left_femur.stl" scale="0.001 0.001 0.001"/>
            </geometry>
        </collision>
        <xacro:inertial_box mass="0.015" x="0.01" y="0.01" z="0.01">
             <origin xyz="-0.08 0 -0.0125"/>
        </xacro:inertial_box>
    </link>
    <gazebo reference="femur5">
        <material>Gazebo/White</material>
    </gazebo>

    <joint name="servo17_joint" type="revolute">
        <parent link="femur5"/>
        <child link="servo17"/>
        <origin xyz="-0.0775 0 0" rpy="0 0 ${pi/4}"/>
        <axis xyz="0 0 1" />
        <limit lower="-0.785398" upper="0.785398" effort="0.8825985000000001" velocity="1.0"/>
    </joint>

    <link name="servo17">
        <visual>
            <origin xyz="-0.008 0 0" rpy="${pi/2} ${pi/2} 0"/>
            <geometry>
                <box size="0.0405 0.0395 0.02"/>
            </geometry>
            <material name="black"/>
        </visual>
        <collision>
            <origin xyz="-0.008 0 0" rpy="${pi/2} ${pi/2} 0"/>
            <geometry>
                <box size="0.0405 0.0395 0.02"/>
            </geometry>
        </collision>
        <xacro:inertial_box mass="0.055" x="0.0405" y="0.0395" z="0.02">
            <origin xyz="-0.008 0 0" rpy="${pi/2} ${pi/2} 0"/>
        </xacro:inertial_box>
    </link>
    <gazebo reference="servo17">
        <material>Gazebo/Black</material>
    </gazebo>

    <joint name="tibia5_joint" type="fixed">
        <parent link="servo17"/>
        <child link="tibia5"/>
        <origin xyz="0 0 0" rpy="-${pi/2} 0 -0.85"/>
    </joint>

    <link name="tibia5">
        <visual>
            <origin xyz="-0.055 0 0.005"/>
            <geometry>
                <mesh filename="file://$(find hexapod)/meshes/left_tibia.stl" scale="0.001 0.001 0.001"/>
            </geometry>
            <material name="white"/>
        </visual>
        <collision>
            <origin xyz="-0.055 0 0.005"/>
            <geometry>
                <mesh filename="file://$(find hexapod)/meshes/left_tibia.stl" scale="0.001 0.001 0.001"/>
            </geometry>
        </collision>
        <xacro:inertial_box mass="0.015" x="0.01" y="0.01" z="0.01">
            <origin xyz="-0.055 0 0.005"/>
        </xacro:inertial_box>
    </link>
    <gazebo reference="tibia5">
        <material>Gazebo/White</material>
    </gazebo>

    <joint name="shield5_joint" type="fixed">
        <parent link="tibia5"/>
        <child link="shield5"/>
        <origin xyz="0 0 0" rpy="0 0 0"/>
    </joint>

    <link name="shield5">
        <visual>
            <origin xyz="-0.055 -0.01 0"/>
            <geometry>
                <mesh filename="file://$(find hexapod)/meshes/shield.stl" scale="0.001 0.001 0.001"/>
            </geometry>
            <material name="blue"/>
        </visual>
        <collision>
            <origin xyz="-0.055 -0.01 0"/>
            <geometry>
                <mesh filename="file://$(find hexapod)/meshes/shield.stl" scale="0.001 0.001 0.001"/>
            </geometry>
        </collision>
        <xacro:inertial_box mass="0.015" x="0.01" y="0.01" z="0.01">
            <origin xyz="-0.055 -0.01 0"/>
        </xacro:inertial_box>
    </link>
    <gazebo reference="shield5">
        <material>Gazebo/Blue</material>
    </gazebo>

    <joint name="sensor5_joint" type="fixed">
        <parent link="tibia5"/>
        <child link="sensor5"/>
        <origin xyz="0 0 0" rpy="0 0 0"/>
    </joint>

    <link name="sensor5">
        <visual>
            <origin xyz="-0.0425 -0.005 -0.125"/>
            <geometry>
                <mesh filename="file://$(find hexapod)/meshes/micro_switch_tip.stl" scale="0.001 0.001 0.001"/>
            </geometry>
            <material name="white"/>
        </visual>
        <collision>
            <origin xyz="-0.0425 -0.005 -0.125"/>
            <geometry>
                <mesh filename="file://$(find hexapod)/meshes/micro_switch_tip.stl" scale="0.001 0.001 0.001"/>
            </geometry>
        </collision>
        <xacro:inertial_box mass="0.015" x="0.01" y="0.01" z="0.01">
             <origin xyz="-0.0425 -0.005 -0.125"/>
        </xacro:inertial_box>
    </link>
    <gazebo reference="sensor5">
        <material>Gazebo/White</material>
    </gazebo>

    <!-- LEG 6 (LF) -->

    <joint name="coxa6_joint" type="revolute">
        <parent link="servo6"/>
        <child link="coxa6"/>
        <origin xyz="-0.06 0.085 0" rpy="0 0 ${(3*pi)/4}"/>
        <axis xyz="0 0 1" />
        <limit lower="-0.785398" upper="0.785398" effort="0.8825985000000001" velocity="1.0"/>
    </joint>

    <link name="coxa6">
        <visual>
            <origin xyz="0 0 -0.005"/>
            <geometry>
                <mesh filename="file://$(find hexapod)/meshes/left_coxa.stl" scale="0.001 0.001 0.001"/>
            </geometry>
            <material name="white"/>
        </visual>
        <collision>
            <origin xyz="0 0 -0.005"/>
            <geometry>
                <mesh filename="file://$(find hexapod)/meshes/left_coxa.stl" scale="0.001 0.001 0.001"/>
            </geometry>
        </collision>
        <xacro:inertial_box mass="0.015" x="0.01" y="0.01" z="0.01">
            <origin xyz="0 0 0" rpy="0 0 0"/>
        </xacro:inertial_box>
    </link>
    <gazebo reference="coxa6">
        <material>Gazebo/White</material>
    </gazebo>

    <joint name="servo12_joint" type="fixed">
        <parent link="coxa6"/>
        <child link="servo12"/>
        <origin xyz="0 0 0"/>
    </joint>

    <link name="servo12">
        <visual>
            <origin xyz="0.045 0 0.0095" rpy="0 ${pi/2} 0"/>
            <geometry>
                <box size="0.0405 0.0395 0.02"/>
            </geometry>
            <material name="black"/>
        </visual>
        <collision>
            <origin xyz="0.045 0 0.0095" rpy="0 ${pi/2} 0"/>
            <geometry>
                <box size="0.0405 0.0395 0.02"/>
            </geometry>
        </collision>
        <xacro:inertial_box mass="0.055" x="0.0405" y="0.0395" z="0.02">
            <origin xyz="0.045 0 0.0095" rpy="0 ${pi/2} 0"/>
        </xacro:inertial_box>
    </link>
    <gazebo reference="servo12">
        <material>Gazebo/Black</material>
    </gazebo>

    <joint name="femur6_joint" type="revolute">
        <parent link="servo12"/>
        <child link="femur6"/>
        <origin xyz="0.045 0 0.02" rpy="${pi/2} ${pi/4} ${pi}"/>
        <axis xyz="0 0 1" />
        <limit lower="-0.785398" upper="0.785398" effort="0.8825985000000001" velocity="1.0"/>
    </joint>

    <link name="femur6">
        <visual>
            <origin xyz="-0.08 0 0.0125"/>
            <geometry>
                <mesh filename="file://$(find hexapod)/meshes/left_femur.stl" scale="0.001 0.001 0.001"/>
            </geometry>
            <material name="white"/>
        </visual>
        <collision>
             <origin xyz="-0.08 0 -0.0125"/>
            <geometry>
                <mesh filename="file://$(find hexapod)/meshes/left_femur.stl" scale="0.001 0.001 0.001"/>
            </geometry>
        </collision>
        <xacro:inertial_box mass="0.015" x="0.01" y="0.01" z="0.01">
             <origin xyz="-0.08 0 -0.0125"/>
        </xacro:inertial_box>
    </link>
    <gazebo reference="femur6">
        <material>Gazebo/White</material>
    </gazebo>

    <joint name="servo18_joint" type="revolute">
        <parent link="femur6"/>
        <child link="servo18"/>
        <origin xyz="-0.0775 0 0" rpy="0 0 ${pi/4}"/>
        <axis xyz="0 0 1" />
        <limit lower="-0.785398" upper="0.785398" effort="0.8825985000000001" velocity="1.0"/>
    </joint>

    <link name="servo18">
        <visual>
            <origin xyz="-0.008 0 0" rpy="${pi/2} ${pi/2} 0"/>
            <geometry>
                <box size="0.0405 0.0395 0.02"/>
            </geometry>
            <material name="black"/>
        </visual>
        <collision>
            <origin xyz="-0.008 0 0" rpy="${pi/2} ${pi/2} 0"/>
            <geometry>
                <box size="0.0405 0.0395 0.02"/>
            </geometry>
        </collision>
        <xacro:inertial_box mass="0.055" x="0.0405" y="0.0395" z="0.02">
            <origin xyz="-0.008 0 0" rpy="${pi/2} ${pi/2} 0"/>
        </xacro:inertial_box>
    </link>
    <gazebo reference="servo18">
        <material>Gazebo/Black</material>
    </gazebo>

    <joint name="tibia6_joint" type="fixed">
        <parent link="servo18"/>
        <child link="tibia6"/>
        <origin xyz="0 0 0" rpy="-${pi/2} 0 -0.85"/>
    </joint>

    <link name="tibia6">
        <visual>
            <origin xyz="-0.055 0 0.005"/>
            <geometry>
                <mesh filename="file://$(find hexapod)/meshes/left_tibia.stl" scale="0.001 0.001 0.001"/>
            </geometry>
            <material name="white"/>
        </visual>
        <collision>
            <origin xyz="-0.055 0 0.005"/>
            <geometry>
                <mesh filename="file://$(find hexapod)/meshes/left_tibia.stl" scale="0.001 0.001 0.001"/>
            </geometry>
        </collision>
        <xacro:inertial_box mass="0.015" x="0.01" y="0.01" z="0.01">
            <origin xyz="-0.055 0 0.005"/>
        </xacro:inertial_box>
    </link>
    <gazebo reference="tibia6">
        <material>Gazebo/White</material>
    </gazebo>
    
    <joint name="shield6_joint" type="fixed">
        <parent link="tibia6"/>
        <child link="shield6"/>
        <origin xyz="0 0 0" rpy="0 0 0"/>
    </joint>

    <link name="shield6">
        <visual>
            <origin xyz="-0.055 -0.01 0"/>
            <geometry>
                <mesh filename="file://$(find hexapod)/meshes/shield.stl" scale="0.001 0.001 0.001"/>
            </geometry>
            <material name="blue"/>
        </visual>
        <collision>
            <origin xyz="-0.055 -0.01 0"/>
            <geometry>
                <mesh filename="file://$(find hexapod)/meshes/shield.stl" scale="0.001 0.001 0.001"/>
            </geometry>
        </collision>
        <xacro:inertial_box mass="0.015" x="0.01" y="0.01" z="0.01">
            <origin xyz="-0.055 -0.01 0"/>
        </xacro:inertial_box>
    </link>
    <gazebo reference="shield6">
        <material>Gazebo/Blue</material>
    </gazebo>

    <joint name="sensor6_joint" type="fixed">
        <parent link="tibia6"/>
        <child link="sensor6"/>
        <origin xyz="0 0 0" rpy="0 0 0"/>
    </joint>

    <link name="sensor6">
        <visual>
            <origin xyz="-0.0425 -0.005 -0.125"/>
            <geometry>
                <mesh filename="file://$(find hexapod)/meshes/micro_switch_tip.stl" scale="0.001 0.001 0.001"/>
            </geometry>
            <material name="white"/>
        </visual>
        <collision>
            <origin xyz="-0.0425 -0.005 -0.125"/>
            <geometry>
                <mesh filename="file://$(find hexapod)/meshes/micro_switch_tip.stl" scale="0.001 0.001 0.001"/>
            </geometry>
        </collision>
        <xacro:inertial_box mass="0.015" x="0.01" y="0.01" z="0.01">
             <origin xyz="-0.0425 -0.005 -0.125"/>
        </xacro:inertial_box>
    </link>
    <gazebo reference="sensor6">
        <material>Gazebo/White</material>
    </gazebo>

    <!-- TOP -->

    <joint name="top_cover_joint" type="fixed">
        <parent link="frame"/>
        <child link="top_cover"/>
        <origin xyz="0 0 0"/>
    </joint>

    <link name="top_cover">
        <visual>
            <origin xyz="0 0 0.014"/>
            <geometry>
                <mesh filename="file://$(find hexapod)/meshes/top_cover.stl" scale="0.001 0.001 0.001"/>
            </geometry>
            <material name="blue"/>
        </visual>
        <collision>
            <origin xyz="0 0 0.014"/>
            <geometry>
                <mesh filename="file://$(find hexapod)/meshes/top_cover.stl" scale="0.001 0.001 0.001"/>
            </geometry>
        </collision>
        <xacro:inertial_box mass="0.05" x="0" y="0" z="0">
            <origin xyz="0 0 0.014"/>
        </xacro:inertial_box>
    </link>
    <gazebo reference="top_cover">
        <material>Gazebo/Blue</material>
    </gazebo>

    <joint name="phone_joint" type="fixed">
        <parent link="top_cover"/>
        <child link="phone"/>
        <origin xyz="0 0 0"/>
    </joint>

    <link name="phone">
        <visual>
            <origin xyz="0 0 .024"/>
            <geometry>
                <box size="0.0699 0.1422 0.0079"/>
            </geometry>
            <material name="phone"/>
        </visual>
        <collision>
            <origin xyz="0 0 .024"/>
            <geometry>
                <box size="0.0699 0.1422 0.0079"/>
            </geometry>
        </collision>
        <xacro:inertial_box mass="0.15" x="0.0699" y="0.1422" z="0.0079">
            <origin xyz="0 0 .024"/>
        </xacro:inertial_box>
    </link>
    <gazebo reference="phone">
        <material>Gazebo/Black</material>
    </gazebo>

    <!-- BOTTOM -->

    <joint name="bottom_cover_joint" type="fixed">
        <parent link="frame"/>
        <child link="bottom_cover"/>
        <origin xyz="0 0 0"/>
    </joint>

    <link name="bottom_cover">
        <visual>
            <origin xyz="0 0 .0175"/>
            <geometry>
                <mesh filename="file://$(find hexapod)/meshes/bottom_cover.stl" scale="0.001 0.001 0.001"/>
            </geometry>
            <material name="blue"/>
        </visual>
        <collision>
            <origin xyz="0 0 .0175"/>
            <geometry>
                <mesh filename="file://$(find hexapod)/meshes/bottom_cover.stl" scale="0.001 0.001 0.001"/>
            </geometry>
        </collision>
        <xacro:inertial_box mass="0.045" x="0" y="0" z="0">
            <origin xyz="0 0 .0175"/>
        </xacro:inertial_box>
    </link>
    <gazebo reference="bottom_cover">
        <material>Gazebo/Blue</material>
    </gazebo>

    <joint name="batterybar1_joint" type="fixed">
        <parent link="bottom_cover"/>
        <child link="batterybar1"/>
        <origin xyz="0 0 0"/>
    </joint>

    <link name="batterybar1">
        <visual>
            <origin xyz="0 0.005 .0175"/>
            <geometry>
                <mesh filename="file://$(find hexapod)/meshes/battery_bar.stl" scale="0.001 0.001 0.001"/>
            </geometry>
            <material name="white"/>
        </visual>
        <collision>
            <origin xyz="0 0.005 .0175"/>
            <geometry>
                <mesh filename="file://$(find hexapod)/meshes/battery_bar.stl" scale="0.001 0.001 0.001"/>
            </geometry>
        </collision>
        <xacro:inertial_box mass="0.004" x="0" y="0" z="0">
            <origin xyz="0 0 .0175"/>
        </xacro:inertial_box>
    </link>
    <gazebo reference="batterybar1">
        <material>Gazebo/White</material>
    </gazebo>

    <joint name="batterybar2_joint" type="fixed">
        <parent link="bottom_cover"/>
        <child link="batterybar2"/>
        <origin xyz="0 0 0"/>
    </joint>

    <link name="batterybar2">
        <visual>
            <origin xyz="0 -0.075 .0175"/>
            <geometry>
                <mesh filename="file://$(find hexapod)/meshes/battery_bar.stl" scale="0.001 0.001 0.001"/>
            </geometry>
            <material name="white"/>
        </visual>
        <collision>
            <origin xyz="0 -0.075 .0175"/>
            <geometry>
                <mesh filename="file://$(find hexapod)/meshes/battery_bar.stl" scale="0.001 0.001 0.001"/>
            </geometry>
        </collision>
        <xacro:inertial_box mass="0.004" x="0" y="0" z="0">
            <origin xyz="0 -0.075 .0175"/>
        </xacro:inertial_box>
    </link>
    <gazebo reference="batterybar2">
        <material>Gazebo/White</material>
    </gazebo>

    <joint name="battery_joint" type="fixed">
        <parent link="bottom_cover"/>
        <child link="battery"/>
        <origin xyz="0 0 0"/>
    </joint>

    <link name="battery">
        <visual>
            <origin xyz="0 0 -0.0225"/>
            <geometry>
                <box size="0.047 0.138 0.025"/>
            </geometry>
            <material name="black"/>
        </visual>
        <collision>
            <origin xyz="0 0 -0.0225"/>
            <geometry>
                <box size="0.047 0.138 0.025"/>
            </geometry>
        </collision>
        <xacro:inertial_box mass="0.25" x="0.047" y="0.138" z="-0.025">
            <origin xyz="0 0 -0.0225"/>
        </xacro:inertial_box>
    </link>
    <gazebo reference="battery">
        <material>Gazebo/Black</material>
    </gazebo>

</robot>